Workbook

Sheet Dashboard
A1: Superannuation Planning Report for Emily
A2: Given | B2: Current age (In years) | C2: 30 years
B3: Salary in $ | C3: 70000
B4: Mean Annual Salary growth | C4: 0.035
B5: Standard Deviation on Hike | C5: 0.007 | D5: ---- Hike is randomized using Norm.Inv
B6: Employer Contribution | C6: 0.03
A7: Assumption | B7: Assumed Emily Expenses per annum | C7: ='Retirement Capital'!E12 -> 54000 | D7: ---- Living Expenses, Health, Leisure, Travel
B8: With 2% inflation -Expense need @ 65 years | C8: ='Retirement Capital'!E16 -> 105659.24 | D8: ~ 1.1 Million
B9: Annuity Lifestyle Cost - Required Capital | C9: ='Retirement Capital'!E27 -> 1454757 | D9: ~ 1.5 Million
B10: Scenarios: | C10: Base Case | D10: Best Case | E10: Worst Case
B11: Retirement Age | C11: 65 Years | D11: 67 Years | E11: 60 Years
B12: Total number of Years as employee | C12: 35 Years | D12: 37 Years | E12: 30 Years
B13: Employee Contribution till 45 years | C13: 0.03 | D13: 0.1 | E13: 0.03
B14: Contribution b/w 46 to 60 years | C14: 0.03 | D14: 0.06 | E14: 0.03
B15: Contribution after 60 years | C15: 0.03 | D15: 0.03 | E15: 0.03
A16: Optimisation - Using Solver | B16: Harbour Safe Allocation % | C16: ='Base Case'!D11 -> 0.4 | D16: ='Best Case'!D11 -> 0.1 | E16: ='Worst Case'!D11 -> 0.8
B17: Horizon Allocation % | C17: ='Base Case'!D12 -> 0.3 | D17: ='Best Case'!D12 -> 0.35 | E17: ='Worst Case'!D12 -> 0.1
B18: SkyHigh Allocation % | C18: ='Base Case'!D13 -> 0.3 | D18: ='Best Case'!D13 -> 0.55 | E18: ='Worst Case'!D13 -> 0.1
B19: Expected Portfolio Return % using Solver | C19: ='Base Case'!V9 -> 0.06525 | D19: ='Best Case'!V9 -> 0.082874904 | E19: ='Worst Case'!V9 -> 0.046750037
B20: Volatility - Risk | C20: ='Base Case'!V11 -> 0.072576253 | D20: ='Best Case'!V11 -> 0.1199999 | E20: ='Worst Case'!V11 -> 0.07125005
A21: Monte-Carlo Simulation | B21: Simulation Result for Corpus | C21: ='Base Case'!M9 -> 560346.25 | D21: ='Best Case'!L5 -> 1544067.8 | E21: ='Worst Case'!L5 -> 361000.64
B22: Corpus Shortfall/Surplus | C22: =C21-C9 -> -894410.75 | D22: =D21-C9 -> 89310.8 | E22: =E21-C9 -> -1093756.4
I23: Base Case | K23: Best Case | M23: Worst Case

Sheet Sheet7
D5: Fund | E5: Base Case | F5: Best Case | G5: Worst Case
D6: Harbour Safe Allocation % | E6: 0.4 | F6: 0.1 | G6: 0.8
D7: Horizon Allocation % | E7: 0.3 | F7: 0.35 | G7: 0.1
D8: SkyHigh Allocation % | E8: 0.3 | F8: 0.55 | G8: 0.1

Sheet Retirement Capital
C5: Lifestyle in Retirement (Annual Expenses at Age 65 in Today's Dollars): | S5: inflation | T5: 0.02
S6: Mean | T6: 0.02
C7: Category | D7: Monthly (NZD) | E7: Annual (NZD) | S7: SD | T7: 0.01
C8: Basic Living Expenses | D8: 2500 | E8: =D8*12 -> 30000 | H8: fund in hand | I8: 16000 | M8: =(1+0.0441)^-20 -> 0.42185003 | O8: 0.0441
C9: Healthcare | D9: 500 | E9: =D9*12 -> 6000 | M9: =M8/O8 -> 9.5657603 | S9: =_xlfn.NORM.INV(RAND(),T6,T7) -> 0.013527338
C10: Travel & Leisure | D10: 1000 | E10: =D10*12 -> 12000 | M10: =M9*E16 -> 1010710.9
C11: Miscellaneous/Buffer | D11: 500 | E11: =D11*12 -> 6000
C12: Total (Today’s Value) | D12: =SUM(D8:D11) -> 4500 | E12: =SUM(E8:E11) -> 54000 | R12: Simulation | S12: Inflation
R13: 1 | S13: =S9 -> 0.013527338
C14: Assuming Emily to live till | E14: 85 years | F14: 55 | G14: Year left for Emily (App) | R14: 2 | S14: 0.022041131 | U14: =AVERAGE(S13:S1012) -> 0.019363228
C15: Retirement @65 years | E15: 20 years of retirement | R15: 3 | S15: 0.018414921
C16: 54000$ with inflation at 2% per year | E16: =E12*(1+U14)^35 -> 105659.24 | G16: (Future Expense = Present Expense × (1 + Inflation) ^ Years_to_Retirement) - based on the concept of compound interest. | R16: 4 | S16: 0.025568354
R17: 5 | S17: 0.030965664
R18: 6 | S18: 0.024035462
R19: 7 | S19: 0.019010688
C20: Annuity value - Req for Corpus | R20: 8 | S20: 0.034169338
R21: 9 | S21: 0.024828073
R22: 10 | S22: 0.011888658
C23: Emily needs a retirement corpus of approximately NZD 1.1 million at age 65-70 to fund 20 years of retirement with: | R23: 11 | S23: 0.0097227096
R24: 12 | S24: 0.0019600646
C25: Real return of 4.41% | R25: 13 | S25: 0.024350267
C26: Annual lifestyle cost of NZD 1.1 MILLION | R26: 14 | S26: 0.026998927
C27: Required Corpus is | E27: 1454757 | F27: ~1.5 MILLION | R27: 15 | S27: 0.030164306
R28: 16 | S28: 0.0078301876
R29: 17 | S29: 0.009092948
R30: 18 | S30: 0.0063292396
R31: 19 | S31: 0.018620824
R32: 20 | S32: 0.021421086
R33: 21 | S33: 0.025794052
R34: 22 | S34: 0.0086142293
R35: 23 | S35: 0.025686115
R36: 24 | S36: 0.007105943
R37: 25 | S37: 0.021130283
R38: 26 | S38: 0.032358257
R39: 27 | S39: 0.0376509
... R1012: 1000 | S1012: 0.0087813928

Sheet Sensitivity Report - Base case
A1: Microsoft Excel 16.0 Sensitivity Report
A2: Worksheet: [705 Group Assignment - Sensitivity.xlsx]Base Case
A3: Report Created: 31/05/2025 7:45:25 pm
A6: Variable Cells
D7: Final | E7: Reduced
B8: Cell | C8: Name | D8: Value | E8: Gradient
B9: $V$5 | C9: HarbourSafe Allocation | D9: 0.4 | E9: 0
B10: $V$6 | C10: Horizon Allocation | D10: 0.3 | E10: 0
B11: $V$7 | C11: SkyHigh Allocation | D11: 0.3 | E11: 0
A13: Constraints
D14: Final | E14: Lagrange
B15: Cell | C15: Name | D15: Value | E15: Multiplier
B16: $V$11 | C16: Expected Portfolio Return Allocation | D16: 0.072576253 | E16: 0
B17: $V$8 | C17: Allocation | D17: 1 | E17: 0

Sheet Base Case
C1: Current age (In years) | D1: 30 | O1: Simulation | P1: Final value
C2: Retirement age (In years) | D2: 65 | L2: Final Corpus Value | M2: =M52 -> 610631.47 | O2: 1 | P2: =M2 -> 610631.47
C3: Salary in $ | D3: 70000 | L3: Required Corpus is | M3: ='Retirement Capital'!E27 -> 1454757 | O3: 2 | P3: 541905.86
C4: Mean Annual Salary growth | D4: 0.035 | G4: SD | H4: 0.7 | L4: Difference | M4: =M9-M3 -> -894410.75 | O4: 3 | P4: 543442.33 | S4: Fund | T4: Return | U4: Volatility | V4: Allocation
C5: Contribution rate | D5: 0.03 | O5: 4 | P5: 566010.46 | S5: HarbourSafe | T5: 0.0375 | U5: 0.05 | V5: 0.4
C6: Employer rate | D6: 0.03 | O6: 5 | P6: 549538.61 | S6: Horizon | T6: 0.065 | U6: 0.105 | V6: 0.3
C7: Years to retire | D7: =D2-D1 -> 35 | O7: 6 | P7: 553713.01 | S7: SkyHigh | T7: 0.1025 | U7: 0.2075 | V7: 0.3
O8: 7 | P8: 582738.08 | V8: =SUM(V5:V7) -> 1
L9: Mean Corpus Value based on Monte Carlo | M9: =AVERAGE(P2:P1001) -> 560346.25 | O9: 8 | P9: 544317.28 | V9: =(V5*T5)+(V6*T6)+(V7*T7) -> 0.06525 | W9: Portfolio Return
D10: Allocation | E10: Return | G10: Volatility | O10: 9 | P10: 552599.59
C11: HarbourSafe | D11: 0.4 | E11: 0.0375 | G11: 0.05 | I11: Expected Portfolio Return | J11: =(D11*E11)+(D12*E12)+(D13*E13) -> 0.06525 | O11: 10 | P11: 546002.98 | V11: =SQRT((V5*5%)^2+(V6*10.5%)^2+(V7*20.75%)^2) -> 0.072576253 | W11: Volatility
C12: Horizon | D12: 0.3 | E12: 0.065 | G12: 0.105 | I12: Expected Volatility | J12: 0.073 | O12: 11 | P12: 561595.65
C13: SkyHigh | D13: 0.3 | E13: 0.1025 | G13: 0.2075 | O13: 12 | P13: 576636.11
O14: 13 | P14: 543675.96
O15: 14 | P15: 546611.66
D16: Year | E16: Age | F16: Salary Growth % | G16: Salary | H16: Employee contribution | I16: Employer contribution | J16: Total Contribution | K16: Closing balance (not imp) | L16: Investment return | M16: Total Balance | O16: 15 | P16: 563673.92
D17: 1 | E17: 30 | F17: =_xlfn.NORM.INV(RAND(),0.035,0.007) -> 0.03131067 | G17: 70000 | H17: =G17*3% -> 2100 | I17: =H17 -> 2100 | J17: =H17+I17 -> 4200 | K17: 65800 | L17: 0 | M17: =J17+L17 -> 4200 | O17: 16 | P17: 555964.83
D18: 2 | E18: =E17+1 -> 31 | F18: =_xlfn.NORM.INV(RAND(),0.035,0.007) -> 0.03900411 | G18: =G17*(1+F18) -> 72730.288 | H18: =G18*3% -> 2181.9086 | I18: =H18 -> 2181.9086 | J18: =H18+I18 -> 4363.8173 | K18: 68103 | L18: =(J17*$J$11)+L17 -> 274.05 | M18: =J18+L18+M17 -> 8837.8673 | O18: 17 | P18: 561258.18
D19: 3 | E19: =E18+1 -> 32 | F19: =_xlfn.NORM.INV(RAND(),0.035,0.007) -> 0.04434681 | G19: =G18*(1+F19) -> 75955.644 | H19: =G19*3% -> 2278.6693 | I19: =H19 -> 2278.6693 | J19: =H19+I19 -> 4557.3386 | K19: 70487 | L19: =(J18*$J$11)+L18 -> 558.78908 | M19: =J19+L19+M18 -> 13953.995 | O19: 18 | P19: 554147
D20: 4 | E20: =E19+1 -> 33 | F20: =_xlfn.NORM.INV(RAND(),0.035,0.007) -> 0.037379216 | G20: =G19*(1+F20) -> 78794.806 | H20: =G20*3% -> 2363.8442 | I20: =H20 -> 2363.8442 | J20: =H20+I20 -> 4727.6884 | K20: 72954 | L20: =(J19*$J$11)+L19 -> 856.15542 | M20: =J20+L20+M19 -> 19537.839 | O20: 19 | P20: 583154.42
D21: 5 | E21: =E20+1 -> 34 | F21: =_xlfn.NORM.INV(RAND(),0.035,0.007) -> 0.041901029 | G21: =G20*(1+F21) -> 82096.39 | H21: =G21*3% -> 2462.8917 | I21: =H21 -> 2462.8917 | J21: =H21+I21 -> 4925.7834 | K21: 75507 | L21: =(J20*$J$11)+L20 -> 1164.6371 | M21: =J21+L21+M20 -> 25628.259 | O21: 20 | P21: 568581.07
D22: 6 | E22: =E21+1 -> 35 | F22: =_xlfn.NORM.INV(RAND(),0.035,0.007) -> 0.035927163 | G22: =G21*(1+F22) -> 85045.88 | H22: =G22*3% -> 2551.3764 | I22: =H22 -> 2551.3764 | J22: =H22+I22 -> 5102.7528 | K22: 78150 | L22: =(J21*$J$11)+L21 -> 1486.0445 | M22: =J22+L22+M21 -> 32217.057 | O22: 21 | P22: 530700.22
D23: 7 | E23: =E22+1 -> 36 | F23: =_xlfn.NORM.INV(RAND(),0.035,0.007) -> 0.039016537 | G23: =G22*(1+F23) -> 88364.076 | H23: =G23*3% -> 2650.9223 | I23: =H23 -> 2650.9223 | J23: =H23+I23 -> 5301.8446 | K23: 80885 | L23: =(J22*$J$11)+L22 -> 1818.9991 | M23: =J23+L23+M22 -> 39337.9 | O23: 22 | P23: 570399.95
D24: 8 | E24: =E23+1 -> 37 | F24: =_xlfn.NORM.INV(RAND(),0.035,0.007) -> 0.045954791 | G24: =G23*(1+F24) -> 92424.829 | H24: =G24*3% -> 2772.7449 | I24: =H24 -> 2772.7449 | J24: =H24+I24 -> 5545.4897 | K24: 83716 | L24: =(J23*$J$11)+L23 -> 2164.9444 | M24: =J24+L24+M23 -> 47048.334 | O24: 23 | P24: 560855.7
D25: 9 | E25: =E24+1 -> 38 | F25: =_xlfn.NORM.INV(RAND(),0.035,0.007) -> 0.040711005 | G25: =G24*(1+F25) -> 96187.536 | H25: =G25*3% -> 2885.6261 | I25: =H25 -> 2885.6261 | J25: =H25+I25 -> 5771.2522 | K25: 86646 | L25: =(J24*$J$11)+L24 -> 2526.7876 | M25: =J25+L25+M24 -> 55346.374 | O25: 24 | P25: 552804.6
D26: 10 | E26: =E25+1 -> 39 | F26: =_xlfn.NORM.INV(RAND(),0.035,0.007) -> 0.047906018 | G26: =G25*(1+F26) -> 100795.5 | H26: =G26*3% -> 3023.8649 | I26: =H26 -> 3023.8649 | J26: =H26+I26 -> 6047.7299 | K26: 89679 | L26: =(J25*$J$11)+L25 -> 2903.3618 | M26: =J26+L26+M25 -> 64297.466 | O26: 25 | P26: 570814.25
D27: 11 | E27: =E26+1 -> 40 | F27: =_xlfn.NORM.INV(RAND(),0.035,0.007) -> 0.038858435 | G27: =G26*(1+F27) -> 104712.25 | H27: =G27*3% -> 3141.3676 | I27: =H27 -> 3141.3676 | J27: =H27+I27 -> 6282.7352 | K27: 92817 | L27: =(J26*$J$11)+L26 -> 3297.9762 | M27: =J27+L27+M26 -> 73878.177 | O27: 26 | P27: 572014.04
D28: 12 | E28: =E27+1 -> 41 | F28: =_xlfn.NORM.INV(RAND(),0.035,0.007) -> 0.049420215 | G28: =G27*(1+F28) -> 109887.16 | H28: =G28*3% -> 3296.6147 | I28: =H28 -> 3296.6147 | J28: =H28+I28 -> 6593.2293 | K28: 96066 | L28: =(J27*$J$11)+L27 -> 3707.9247 | M28: =J28+L28+M27 -> 84179.331 | O28: 27 | P28: 564395.46
D29: 13 | E29: =E28+1 -> 42 | F29: =_xlfn.NORM.INV(RAND(),0.035,0.007) -> 0.037781769 | G29: =G28*(1+F29) -> 114038.89 | H29: =G29*3% -> 3421.1666 | I29: =H29 -> 3421.1666 | J29: =H29+I29 -> 6842.3332 | K29: 99428 | L29: =(J28*$J$11)+L28 -> 4138.1329 | M29: =J29+L29+M28 -> 95159.797 | O29: 28 | P29: 557314.27
... D52: 36 | E52: =E51+1 -> 65 | F52: =_xlfn.NORM.INV(RAND(),0.035,0.007) -> 0.044626988 | G52: =G51*(1+F52) -> 269898.24 | H52: =G52*3% -> 8096.9473 | I52: =H52 -> 8096.9473 | J52: =H52+I52 -> 16193.895 | K52: 219350 | L52: =(J51*$J$11)+L51 -> 20117.76 | M52: =J52+L52+M51 -> 610631.47 | O52: 51 | P52: 552152.05
O53: 52 | P53: 573544.42
O54: 53 | P54: 556504
O55: 54 | P55: 569661.61
O56: 55 | P56: 565410.11
O57: 56 | P57: 555249.01
O58: 57 | P58: 560637.28
O59: 58 | P59: 555747.42
O60: 59 | P60: 555290.09
O61: 60 | P61: 563778.5
O62: 61 | P62: 562339.33
...

Sheet Sensitivity Report - Best Case
A1: Microsoft Excel 16.0 Sensitivity Report
A2: Worksheet: [705 Group Assignment - Sensitivity.xlsx]Best Case
A3: Report Created: 31/05/2025 7:34:44 pm
A6: Variable Cells
D7: Final | E7: Reduced
B8: Cell | C8: Name | D8: Value | E8: Gradient
B9: $V$5 | C9: HarbourSafe Allocation | D9: 0.1 | E9: -0.020672794
B10: $V$6 | C10: Horizon Allocation | D10: 0.35000257 | E10: 0
B11: $V$7 | C11: SkyHigh Allocation | D11: 0.54999743 | E11: 0
A13: Constraints
D14: Final | E14: Lagrange
B15: Cell | C15: Name | D15: Value | E15: Multiplier
B16: $V$11 | C16: Expected Portfolio Return Allocation | D16: 0.1199999 | E16: 0.22701975
B17: $V$8 | C17: Years to retire Allocation | D17: 1 | E17: 0.057699834

Sheet Best Case
C1: Current age (In years) | D1: 30 | N1: Simulation | O1: Final value
C2: Retirement age (In years) | D2: 67 | E2: (+ 2 years) | K2: Final Corpus Value | L2: =L54 -> 1611115.1 | N2: 1 | O2: =L2 -> 1611115.1
C3: Salary in $ | D3: 70000 | K3: Required Corpus is | L3: ='Retirement Capital'!E27 -> 1454757 | N3: 2 | O3: 1578784.1
C4: Annual Salary growth | D4: 0.035 | G4: SD | H4: 0.7 | K4: Difference | L4: =L2-L3 -> 156358.14 | N4: 3 | O4: 1483740.2 | S4: Fund | T4: Return | U4: Volatility | V4: Allocation
C5: Contribution rate | D5: 0.1 | K5: Mean Corpus Value based on Monte Carlo | L5: =AVERAGE(O2:O1001) -> 1544067.8 | N5: 4 | O5: 1547411.5 | S5: HarbourSafe | T5: 0.0375 | U5: 0.05 | V5: 0.1
C6: Employer rate | D6: 0.03 | N6: 5 | O6: 1576548.8 | S6: Horizon | T6: 0.065 | U6: 0.105 | V6: 0.35000257
C7: Inflation | D7: 0.02 | N7: 6 | O7: 1472200.6 | S7: SkyHigh | T7: 0.1025 | U7: 0.2075 | V7: 0.54999743
C8: Years to retire | D8: =D2-D1 -> 37 | N8: 7 | O8: 1537070.9 | V8: =SUM(V5:V7) -> 1
N9: 8 | O9: 1482887.3 | V9: =(V5*T5)+(V6*T6)+(V7*T7) -> 0.082874904 | W9: Portfolio return
D10: Allocation | E10: Return | F10: Volatility | N10: 9 | O10: 1542322.4
C11: HarbourSafe | D11: 0.1 | E11: 0.0375 | F11: 0.05 | I11: Expected Portfolio Return | J11: 0.0829 | N11: 10 | O11: 1563779.9 | V11: =SQRT((V5*5%)^2+(V6*10.5%)^2+(V7*20.75%)^2) -> 0.1199999 | W11: Volatility
C12: Horizon | D12: 0.35 | E12: 0.065 | F12: 0.105 | I12: Expected Volatility | J12: 0.12 | N12: 11 | O12: 1610974.7
C13: SkyHigh | D13: 0.55 | E13: 0.1025 | F13: 0.2075 | N13: 12 | O13: 1569964.8
N14: 13 | O14: 1541722.6
N15: 14 | O15: 1555578.9
D16: Year | E16: Age | F16: Salary Growth % | G16: Salary | H16: Employee contribution | I16: Employer contribution | J16: Total Contribution | K16: Investment return | L16: Total Balance | N16: 15 | O16: 1558665
D17: 1 | E17: 30 | F17: =_xlfn.NORM.INV(RAND(),0.035,0.007) -> 0.053570146 | G17: 70000 | H17: =G17*$D$5 -> 7000 | I17: =G17*$D$6 -> 2100 | J17: =H17+I17 -> 9100 | K17: 0 | L17: =J17+K17 -> 9100 | N17: 16 | O17: 1567887
D18: 2 | E18: =E17+1 -> 31 | F18: =_xlfn.NORM.INV(RAND(),0.035,0.007) -> 0.047174988 | G18: =G17*(1+F18) -> 73302.249 | H18: =G18*$D$5 -> 7330.2249 | I18: =G18*$D$6 -> 2199.0675 | J18: =H18+I18 -> 9529.2924 | K18: =(J17*$J$11)+K17 -> 754.39 | L18: =J18+K18+L17 -> 19383.682 | N18: 17 | O18: 1512027.1
D19: 3 | E19: =E18+1 -> 32 | F19: =_xlfn.NORM.INV(RAND(),0.035,0.007) -> 0.034329919 | G19: =G18*(1+F19) -> 75818.709 | H19: =G19*$D$5 -> 7581.8709 | I19: =G19*$D$6 -> 2274.5613 | J19: =H19+I19 -> 9856.4322 | K19: =(J18*$J$11)+K18 -> 1544.3683 | L19: =J19+K19+L18 -> 30784.483 | N19: 18 | O19: 1494686.9
D20: 4 | E20: =E19+1 -> 33 | F20: =_xlfn.NORM.INV(RAND(),0.035,0.007) -> 0.034022103 | G20: =G19*(1+F20) -> 78398.221 | H20: =G20*$D$5 -> 7839.8221 | I20: =G20*$D$6 -> 2351.9466 | J20: =H20+I20 -> 10191.769 | K20: =(J19*$J$11)+K19 -> 2361.4666 | L20: =J20+K20+L19 -> 43337.718 | N20: 19 | O20: 1514084.4
D21: 5 | E21: =E20+1 -> 34 | F21: =_xlfn.NORM.INV(RAND(),0.035,0.007) -> 0.04986735 | G21: =G20*(1+F21) -> 82307.733 | H21: =G21*$D$5 -> 8230.7733 | I21: =G21*$D$6 -> 2469.232 | J21: =H21+I21 -> 10700.005 | K21: =(J20*$J$11)+K20 -> 3206.3642 | L21: =J21+K21+L20 -> 57244.088 | N21: 20 | O21: 1489556
D22: 6 | E22: =E21+1 -> 35 | F22: =_xlfn.NORM.INV(RAND(),0.035,0.007) -> 0.039371576 | G22: =G21*(1+F22) -> 85548.318 | H22: =G22*$D$5 -> 8554.8318 | I22: =G22*$D$6 -> 2566.4495 | J22: =H22+I22 -> 11121.281 | K22: =(J21*$J$11)+K21 -> 4093.3946 | L22: =J22+K22+L21 -> 72458.764 | N22: 21 | O22: 1502077.6
D23: 7 | E23: =E22+1 -> 36 | F23: =_xlfn.NORM.INV(RAND(),0.035,0.007) -> 0.042873109 | G23: =G22*(1+F23) -> 89216.041 | H23: =G23*$D$5 -> 8921.6041 | I23: =G23*$D$6 -> 2676.4812 | J23: =H23+I23 -> 11598.085 | K23: =(J22*$J$11)+K22 -> 5015.3489 | L23: =J23+K23+L22 -> 89072.198 | N23: 22 | O23: 1606982.7
D24: 8 | E24: =E23+1 -> 37 | F24: =_xlfn.NORM.INV(RAND(),0.035,0.007) -> 0.021614339 | G24: =G23*(1+F24) -> 91144.386 | H24: =G24*$D$5 -> 9114.4386 | I24: =G24*$D$6 -> 2734.3316 | J24: =H24+I24 -> 11848.77 | K24: =(J23*$J$11)+K23 -> 5976.8301 | L24: =J24+K24+L23 -> 106897.8 | N24: 23 | O24: 1634436.7
D25: 9 | E25: =E24+1 -> 38 | F25: =_xlfn.NORM.INV(RAND(),0.035,0.007) -> 0.035072524 | G25: =G24*(1+F25) -> 94341.05 | H25: =G25*$D$5 -> 9434.105 | I25: =G25*$D$6 -> 2830.2315 | J25: =H25+I25 -> 12264.336 | K25: =(J24*$J$11)+K24 -> 6959.0932 | L25: =J25+K25+L24 -> 126121.23 | N25: 24 | O25: 1574567.4
D26: 10 | E26: =E25+1 -> 39 | F26: =_xlfn.NORM.INV(RAND(),0.035,0.007) -> 0.047142969 | G26: =G25*(1+F26) -> 98788.567 | H26: =G26*$D$5 -> 9878.8567 | I26: =G26*$D$6 -> 2963.657 | J26: =H26+I26 -> 12842.514 | K26: =(J25*$J$11)+K25 -> 7975.8067 | L26: =J26+K26+L25 -> 146939.55 | N26: 25 | O26: 1521440.3
D27: 11 | E27: =E26+1 -> 40 | F27: =_xlfn.NORM.INV(RAND(),0.035,0.007) -> 0.029216521 | G27: =G26*(1+F27) -> 101674.83 | H27: =G27*$D$5 -> 10167.483 | I27: =G27*$D$6 -> 3050.2448 | J27: =H27+I27 -> 13217.727 | K27: =(J26*$J$11)+K26 -> 9040.4511 | L27: =J27+K27+L26 -> 169197.73 | N27: 26 | O27: 1525451.3
D28: 12 | E28: =E27+1 -> 41 | F28: =_xlfn.NORM.INV(RAND(),0.035,0.007) -> 0.037904934 | G28: =G27*(1+F28) -> 105528.8 | H28: =G28*$D$5 -> 10552.88 | I28: =G28*$D$6 -> 3165.8641 | J28: =H28+I28 -> 13718.744 | K28: =(J27*$J$11)+K27 -> 10136.201 | L28: =J28+K28+L27 -> 193052.67 | N28: 27 | O28: 1507466.7
D29: 13 | E29: =E28+1 -> 42 | F29: =_xlfn.NORM.INV(RAND(),0.035,0.007) -> 0.040958633 | G29: =G28*(1+F29) -> 109851.12 | H29: =G29*$D$5 -> 10985.112 | I29: =G29*$D$6 -> 3295.5336 | J29: =H29+I29 -> 14280.645 | K29: =(J28*$J$11)+K28 -> 11273.485 | L29: =J29+K29+L28 -> 218606.8 | N29: 28 | O29: 1470444.9
... D54: 38 | E54: =E53+1 -> 67 | F54: =_xlfn.NORM.INV(RAND(),0.035,0.007) -> 0.034052153 | G54: =G53*(1+F54) -> 268014.95 | H54: =G54*$D$5 -> 26801.495 | I54: =G54*$D$6 -> 8040.4485 | J54: =H54+I54 -> 34841.943 | K54: =(J53*$J$11)+K53 -> 58265.723 | L54: =J54+K54+L53 -> 1611115.1 | N54: 53 | O54: 1547758
N55: 54 | O55: 1528372.8
N56: 55 | O56: 1527009.8
N57: 56 | O57: 1506031.3
N58: 57 | O58: 1536747.4
N59: 58 | O59: 1505101.4
N60: 59 | O60: 1576768.4
N61: 60 | O61: 1508010.4
N62: 61 | O62: 1496505.5
N63: 62 | O63: 1523296.2
N64: 63 | O64: 1515375
...

Sheet Sensitivity Report - Worst Case
A1: Microsoft Excel 16.0 Sensitivity Report
A2: Worksheet: [705 Group Assignment - Sensitivity.xlsx]Worst Case
A3: Report Created: 31/05/2025 7:37:20 pm
A6: Variable Cells
D7: Final | E7: Reduced
B8: Cell | C8: Name | D8: Value | E8: Gradient
B9: $V$5 | C9: HarbourSafe Allocation | D9: 0.800001 | E9: 0
B10: $V$6 | C10: Horizon Allocation | D10: 0.1 | E10: 0.027499996
B11: $V$7 | C11: SkyHigh Allocation | D11: 0.1 | E11: 0.064999998
A13: Constraints
D14: Final | E14: Lagrange
B15: Cell | C15: Name | D15: Value | E15: Multiplier
B16: $V$11 | C16: Expected Portfolio Return Allocation | D16: 0.07125005 | E16: 0
B17: $V$8 | C17: Years to retire Allocation | D17: 1.000001 | E17: 0.037500001

Sheet Worst Case
B1: A | C1: Current age (In years) | D1: 30 | N1: Simulation | O1: Final value
B2: B | C2: Retirement age (In years) | D2: 60 | K2: Final Value | L2: =L47 -> 359081.3 | N2: 1 | O2: =L2 -> 359081.3
B3: C | C3: Salary in $ | D3: 70000 | K3: Required Corpus is | L3: ='Retirement Capital'!E27 -> 1454757 | N3: 2 | O3: 365607.46
B4: D | C4: Annual Salary growth | D4: 0.035 | G4: SD | H4: 0.7 | K4: Difference | L4: =L2-L3 -> -1095675.7 | N4: 3 | O4: 359008.98 | S4: Fund | T4: Return | U4: Volatility | V4: Allocation
B5: E | C5: Contribution rate | D5: 0.03 | K5: Mean Corpus Value based on Monte Carlo | L5: =AVERAGE(O2:O1001) -> 361000.64 | N5: 4 | O5: 351435.26 | S5: HarbourSafe | T5: 0.0375 | U5: 0.05 | V5: 0.800001
B6: F | C6: Employer rate | D6: 0.03 | N6: 5 | O6: 346875.39 | S6: Horizon | T6: 0.065 | U6: 0.105 | V6: 0.1
B7: G | C7: Inflation | D7: 0.02 | N7: 6 | O7: 367861.9 | S7: SkyHigh | T7: 0.1025 | U7: 0.2075 | V7: 0.1
B8: H | C8: Years to retire | D8: 30 | N8: 7 | O8: 360443.8 | V8: =SUM(V5:V7) -> 1.000001
N9: 8 | O9: 360730.09 | V9: =(V5*T5)+(V6*T6)+(V7*T7) -> 0.046750037 | W9: Portfolio return
D10: Allocation | E10: Return | G10: Volatility | N10: 9 | O10: 365042.82
C11: HarbourSafe | D11: 0.8 | E11: 0.0375 | G11: 0.05 | I11: Expected Portfolio Return | J11: 0.047 | N11: 10 | O11: 369119.82 | V11: =(V5*5%)+(V6*10.5%)+(V7*20.75%) -> 0.07125005 | W11: Volatility
C12: Horizon | D12: 0.1 | E12: 0.065 | G12: 0.105 | I12: Expected Volatility | J12: =(D11*G11)+(D12*G12)+(D13*G13) -> 0.07125 | N12: 11 | O12: 370764.66
C13: SkyHigh | D13: 0.1 | E13: 0.1025 | G13: 0.2075 | N13: 12 | O13: 359215.3
N14: 13 | O14: 358303.86
N15: 14 | O15: 368497.14
D16: Year | E16: Age | F16: Salary Growth % | G16: Salary | H16: Employee contribution | I16: Employer contribution | J16: Total Contribution | K16: Investment return | L16: Total Balance | N16: 15 | O16: 358140.48
D17: 1 | E17: 30 | F17: =_xlfn.NORM.INV(RAND(),0.035,0.007) -> 0.02993805 | G17: 70000 | H17: =G17*$D$5 -> 2100 | I17: =G17*$D$6 -> 2100 | J17: =H17+I17 -> 4200 | K17: 0 | L17: =J17+K17 -> 4200 | N17: 16 | O17: 350657.14
D18: 2 | E18: =E17+1 -> 31 | F18: =_xlfn.NORM.INV(RAND(),0.035,0.007) -> 0.039047492 | G18: =G17*(1+F18) -> 72733.324 | H18: =G18*$D$5 -> 2181.9997 | I18: =G18*$D$6 -> 2181.9997 | J18: =H18+I18 -> 4363.9995 | K18: =(J17*$J$11)+K17 -> 197.4 | L18: =J18+K18+L17 -> 8761.3995 | N18: 17 | O18: 354090.13
D19: 3 | E19: =E18+1 -> 32 | F19: =_xlfn.NORM.INV(RAND(),0.035,0.007) -> 0.03157256 | G19: =G18*(1+F19) -> 75029.702 | H19: =G19*$D$5 -> 2250.891 | I19: =G19*$D$6 -> 2250.891 | J19: =H19+I19 -> 4501.7821 | K19: =(J18*$J$11)+K18 -> 402.50797 | L19: =J19+K19+L18 -> 13665.69 | N19: 18 | O19: 344365.2
D20: 4 | E20: =E19+1 -> 33 | F20: =_xlfn.NORM.INV(RAND(),0.035,0.007) -> 0.037255681 | G20: =G19*(1+F20) -> 77824.984 | H20: =G20*$D$5 -> 2334.7495 | I20: =G20*$D$6 -> 2334.7495 | J20: =H20+I20 -> 4669.4991 | K20: =(J19*$J$11)+K19 -> 614.09173 | L20: =J20+K20+L19 -> 18949.28 | N20: 19 | O20: 369112.33
D21: 5 | E21: =E20+1 -> 34 | F21: =_xlfn.NORM.INV(RAND(),0.035,0.007) -> 0.031152456 | G21: =G20*(1+F21) -> 80249.424 | H21: =G21*$D$5 -> 2407.4827 | I21: =G21*$D$6 -> 2407.4827 | J21: =H21+I21 -> 4814.9654 | K21: =(J20*$J$11)+K20 -> 833.55819 | L21: =J21+K21+L20 -> 24597.804 | N21: 20 | O21: 363269.45
D22: 6 | E22: =E21+1 -> 35 | F22: =_xlfn.NORM.INV(RAND(),0.035,0.007) -> 0.037521175 | G22: =G21*(1+F22) -> 83260.476 | H22: =G22*$D$5 -> 2497.8143 | I22: =G22*$D$6 -> 2497.8143 | J22: =H22+I22 -> 4995.6286 | K22: =(J21*$J$11)+K21 -> 1059.8616 | L22: =J22+K22+L21 -> 30653.294 | N22: 21 | O22: 364210.83
D23: 7 | E23: =E22+1 -> 36 | F23: =_xlfn.NORM.INV(RAND(),0.035,0.007) -> 0.03770136 | G23: =G22*(1+F23) -> 86399.51 | H23: =G23*$D$5 -> 2591.9853 | I23: =G23*$D$6 -> 2591.9853 | J23: =H23+I23 -> 5183.9706 | K23: =(J22*$J$11)+K22 -> 1294.6561 | L23: =J23+K23+L22 -> 37131.921 | N23: 22 | O23: 365219.67
D24: 8 | E24: =E23+1 -> 37 | F24: =_xlfn.NORM.INV(RAND(),0.035,0.007) -> 0.028150258 | G24: =G23*(1+F24) -> 88831.678 | H24: =G24*$D$5 -> 2664.9503 | I24: =G24*$D$6 -> 2664.9503 | J24: =H24+I24 -> 5329.9007 | K24: =(J23*$J$11)+K23 -> 1538.3027 | L24: =J24+K24+L23 -> 44000.124 | N24: 23 | O24: 364685.85
D25: 9 | E25: =E24+1 -> 38 | F25: =_xlfn.NORM.INV(RAND(),0.035,0.007) -> 0.032650114 | G25: =G24*(1+F25) -> 91732.042 | H25: =G25*$D$5 -> 2751.9613 | I25: =G25*$D$6 -> 2751.9613 | J25: =H25+I25 -> 5503.9225 | K25: =(J24*$J$11)+K24 -> 1788.8081 | L25: =J25+K25+L24 -> 51292.855 | N25: 24 | O25: 371940.62
D26: 10 | E26: =E25+1 -> 39 | F26: =_xlfn.NORM.INV(RAND(),0.035,0.007) -> 0.040684801 | G26: =G25*(1+F26) -> 95464.142 | H26: =G26*$D$5 -> 2863.9243 | I26: =G26*$D$6 -> 2863.9243 | J26: =H26+I26 -> 5727.8485 | K26: =(J25*$J$11)+K25 -> 2047.4924 | L26: =J26+K26+L25 -> 59068.196 | N26: 25 | O26: 350157.37
D27: 11 | E27: =E26+1 -> 40 | F27: =_xlfn.NORM.INV(RAND(),0.035,0.007) -> 0.03712711 | G27: =G26*(1+F27) -> 99008.45 | H27: =G27*$D$5 -> 2970.2535 | I27: =G27*$D$6 -> 2970.2535 | J27: =H27+I27 -> 5940.507 | K27: =(J26*$J$11)+K26 -> 2316.7013 | L27: =J27+K27+L26 -> 67325.404 | N27: 26 | O27: 340725.88
D28: 12 | E28: =E27+1 -> 41 | F28: =_xlfn.NORM.INV(RAND(),0.035,0.007) -> 0.036518457 | G28: =G27*(1+F28) -> 102624.09 | H28: =G28*$D$5 -> 3078.7226 | I28: =G28*$D$6 -> 3078.7226 | J28: =H28+I28 -> 6157.4452 | K28: =(J27*$J$11)+K27 -> 2595.9051 | L28: =J28+K28+L27 -> 76078.754 | N28: 27 | O28: 359676.9
D29: 13 | E29: =E28+1 -> 42 | F29: =_xlfn.NORM.INV(RAND(),0.035,0.007) -> 0.040639254 | G29: =G28*(1+F29) -> 106794.65 | H29: =G29*$D$5 -> 3203.8396 | I29: =G29*$D$6 -> 3203.8396 | J29: =H29+I29 -> 6407.6791 | K29: =(J28*$J$11)+K28 -> 2885.305 | L29: =J29+K29+L28 -> 85371.738 | N29: 28 | O29: 332643
... D47: 31 | E47: =E46+1 -> 60 | F47: =_xlfn.NORM.INV(RAND(),0.035,0.007) -> 0.034466633 | G47: =G46*(1+F47) -> 195331.41 | H47: =G47*$D$5 -> 5859.9423 | I47: =G47*$D$6 -> 5859.9423 | J47: =H47+I47 -> 11719.885 | K47: =(J46*$J$11)+K46 -> 10126.578 | L47: =J47+K47+L46 -> 359081.3 | N47: 46 | O47: 359939.77
N48: 47 | O48: 355116.23
N49: 48 | O49: 351358
N50: 49 | O50: 353969.71
N51: 50 | O51: 357967.35
N52: 51 | O52: 353161.44
N53: 52 | O53: 364742.91
N54: 53 | O54: 368521.9
N55: 54 | O55: 370458.43
N56: 55 | O56: 361513.62
N57: 56 | O57: 360814.85
...
